Workbook

Sheet Hướng dẫn
A1: KẾ HOẠCH NỘI DUNG TIẾNG HÀN SEIU – THÁNG 10/2026
A3: Cách dùng file
A4: 1. Tab "Lịch tháng 10": mỗi dòng là 1 bài/video cần đăng. Cột "Kịch bản #" trỏ tới tab "30 kịch bản TikTok".
A5: 2. Ô nền vàng là ô cần cập nhật: Trạng thái (chọn trong danh sách), Người phụ trách, Link bài, Lượt xem.
A6: 3. Tab "KPI tháng": nhập số thực tế ở cột C (nền vàng); cột % đạt và bảng đếm tiến độ tự tính.
A7: 4. Dòng đầu tiên của lịch đã điền ví dụ (Người phụ trách, Link) để biết cách ghi; xóa hoặc sửa khi dùng thật.
A9: Lưu ý nội dung
A10: • Chỉ quay và đăng hình học viên, phụ huynh khi đã được đồng ý; che số hộ chiếu, visa, địa chỉ.
A11: • Không hứa "đậu 100%", "Top 1%" hoặc số liệu chưa có bằng chứng.
A12: • Mọi video gắn logo SEIU góc phải, phụ đề tiếng Việt, kết bằng CTA của kịch bản.
A13: • Chi phí sinh hoạt, quy định làm thêm… là thông tin tham khảo, cần ghi rõ khi đăng.
A15: Trụ cột nội dung (tỷ lệ mục tiêu)
A16: Học tiếng Hàn 30% · Du học thật 25% · Đời sống SEIU 20% · Minh bạch chi phí 15% · Thầy Bửu 10%

Sheet 30 kịch bản TikTok
A1: # | B1: Trụ cột | C1: Tên video | D1: Hook (3 giây đầu) | E1: Nội dung / cảnh quay | F1: CTA cuối video | G1: Hashtag | H1: Thời lượng | I1: Người thực hiện | J1: Trạng thái
A2: 1 | B2: Du học thật | C2: Đi du học Hàn với 75 triệu phí dịch vụ | D2: "75 triệu này gồm những gì? Mình bóc từng khoản cho bạn xem." | E2: Học viên (hoặc thầy Bửu) cầm bảng chi phí, chỉ từng khoản: học phí VN 7tr, invoice trường, phí dịch vụ 75tr thu sau khi đậu visa. Kết: "Không có khoản ẩn." | F2: Bình luận "CHI PHÍ" để nhận bảng dự toán | G2: #duhochanquoc #chiphiduhoc #seiu | H2: 45s | J2: Chưa làm
A3: 2 | B3: Thầy Bửu | C3: 3 câu Lãnh sự quán hay hỏi nhất | D3: "Câu thứ 3 là câu nhiều bạn rớt nhất." | E3: Thầy Bửu đọc 3 câu hỏi phỏng vấn bằng tiếng Hàn, học viên trả lời, thầy sửa lỗi. Chèn chữ Hàn + nghĩa Việt. | F3: Luyện phỏng vấn AI miễn phí trên tienghanseiu.com | G3: #phongvanvisa #visahanquoc #seiu | H3: 60s | J3: Chưa làm
A4: 3 | B4: Học tiếng Hàn | C4: Đọc đúng câu này là đạt TOPIK 2 | D4: "90% người mới đọc sai câu này." | E4: Hiện 1 câu có nối âm (한국어를 배워요). Đếm 3s cho người xem đọc, rồi phát âm chuẩn + giải thích quy tắc. | F4: Làm đề TOPIK miễn phí – link bio | G4: #topik #hoctienghan #seiu | H4: 20s | J4: Chưa làm
A5: 4 | B5: Đời sống SEIU | C5: Khoảnh khắc nhận visa | D5: "Mẹ ơi, con đậu rồi!" | E5: Quay thật phản ứng học viên/phụ huynh khi nhận kết quả visa (xin phép trước, che thông tin cá nhân). | F5: Theo dõi để xem hành trình sang Hàn | G5: #visahanquoc #duhoc #haugiang | H5: 30s | J5: Chưa làm
A6: 5 | B6: Minh bạch chi phí | C6: Cảnh báo 3 chiêu "vẽ phí" du học | D6: "Nếu trung tâm bắt bạn đóng tiền trước khi có visa… dừng lại." | E6: Liệt kê 3 dấu hiệu: thu toàn bộ phí trước, hứa đậu 100%, ép chọn trường. Kết bằng chính sách SEIU. | F6: Lưu video gửi cho phụ huynh | G6: #duhochanquoc #canhbao #phuhuynh | H6: 40s | J6: Chưa làm
A7: 6 | B7: Đời sống SEIU | C7: Một ngày ở lớp SEIU Vị Thanh | D7: "Học tiếng Hàn ở Vị Thanh trông như thế này." | E7: Vlog nhanh: vào lớp, học bảng chữ cái, trò chơi từ vựng, sửa phát âm, tan lớp. Nhạc vui. | F7: Đăng ký học thử 3 buổi miễn phí | G7: #hoctienghanvithanh #haugiang #seiu | H7: 30s | J7: Chưa làm
A8: 7 | B8: Học tiếng Hàn | C8: Người miền Tây nói tiếng Hàn: lỗi hay gặp | D8: "Nói 어 thành 오 là người nghe hiểu sai liền." | E8: So sánh khẩu hình ㅓ/ㅗ, ㅐ/ㅔ bằng ví dụ vui (거기/고기). Học viên thử, thầy sửa. | F8: Tag đứa bạn hay đọc sai | G8: #phatamtienghan #mientay #seiu | H8: 30s | J8: Chưa làm
A9: 8 | B9: Thầy Bửu | C9: Học lực trung bình có du học được không? | D9: "Câu này phụ huynh hỏi mình nhiều nhất." | E9: Thầy Bửu trả lời thẳng: điều kiện GPA theo trường, lựa chọn hệ tiếng D4-1, vai trò TOPIK. Không hứa chắc chắn. | F9: Nhắn Zalo 0972 249 450 để kiểm tra hồ sơ | G9: #duhochanquoc #hocluc #seiu | H9: 60s | J9: Chưa làm
A10: 9 | B10: Du học thật | C10: Học viên SEIU gọi video từ Hàn về lớp cũ | D10: "Bạn này mới học ở đây 1 năm trước." | E10: Quay màn hình cuộc gọi, học viên kể cuộc sống, lời khuyên cho đàn em. Lớp cũ hỏi đáp. | F10: Theo dõi series "SEIU ở Hàn" | G10: #duhocsinhhan #seiu #songohan | H10: 60s | J10: Chưa làm
A11: 10 | B11: Học tiếng Hàn | C11: Thi thử TOPIK Master miễn phí | D11: "Mình thử làm đề TOPIK 70 câu trên web này." | E11: Quay màn hình điện thoại: vào tienghanseiu.com, làm vài câu nghe, nộp bài, xem điểm và Bảng Thành Tích. | F11: Thử ngay – link bio | G11: #topik #thithutopik #seiu | H11: 30s | J11: Chưa làm
A12: 11 | B12: Học tiếng Hàn | C12: 5 câu chào hỏi phải biết | D12: "Nói 안녕하세요 thôi là chưa đủ." | E12: 5 câu: 안녕하세요, 처음 뵙겠습니다, 감사합니다, 죄송합니다, 안녕히 계세요 – kèm tình huống dùng. | F12: Lưu lại học mỗi ngày | G12: #tienghancoban #hoctienghan #seiu | H12: 25s | J12: Chưa làm
A13: 12 | B13: Du học thật | C13: Tiền nhà, tiền ăn ở Hàn 1 tháng | D13: "Một tháng ở Hàn mình tiêu hết bao nhiêu?" | E13: Học viên bên Hàn liệt kê chi phí thực tế (nhà, ăn, đi lại, điện thoại). Ghi rõ là trải nghiệm cá nhân. | F13: Hỏi thêm ở bình luận | G13: #chiphisinhhoat #duhochan #seiu | H13: 45s | J13: Chưa làm
... A31: 30 | B31: Học tiếng Hàn | C31: Thử thách 30 ngày tiếng Hàn | D31: "Mỗi ngày 1 câu, 30 ngày bạn nói được gì?" | E31: Giới thiệu series 30 ngày, câu đầu tiên + bài tập về nhà ở bình luận. | F31: Follow để không lỡ ngày 2 | G31: #30ngaytienghan #thuthach #seiu | H31: 30s | J31: Chưa làm

Sheet Lịch tháng 10
A1: Ngày | B1: Thứ | C1: Kênh | D1: Trụ cột | E1: Nội dung | F1: Kịch bản # | G1: Người phụ trách | H1: Trạng thái | I1: Link bài | J1: Lượt xem
A2: 46296 | B2: Thứ 5 | C2: TikTok + Reels | D2: Du học thật | E2: Đi du học Hàn với 75 triệu phí dịch vụ | F2: 1 | G2: Ví dụ: Linh | H2: Chưa làm | I2: https://www.tiktok.com/@tienghanseiu/video/...
A3: 46296 | B3: Thứ 5 | C3: Website + Facebook | D3: Học tiếng Hàn | E3: Chia sẻ bài blog: TOPIK là gì? Cấp độ, thang điểm | H3: Chưa làm
A4: 46297 | B4: Thứ 6 | C4: TikTok + Reels | D4: Thầy Bửu | E4: 3 câu Lãnh sự quán hay hỏi nhất | F4: 2 | H4: Chưa làm
A5: 46297 | B5: Thứ 6 | C5: Facebook | D5: Du học thật | E5: Chia sẻ câu chuyện 1 học viên SEIU ở Hàn | H5: Chưa làm
A6: 46298 | B6: Thứ 7 | C6: Facebook | D6: Học tiếng Hàn | E6: Mini quiz tiếng Hàn – trả lời ở bình luận | H6: Chưa làm
A7: 46300 | B7: Thứ 2 | C7: TikTok + Reels | D7: Học tiếng Hàn | E7: Đọc đúng câu này là đạt TOPIK 2 | F7: 3 | H7: Chưa làm
A8: 46300 | B8: Thứ 2 | C8: Facebook | D8: Đời sống SEIU | E8: Album ảnh lớp tuần qua + lịch khai giảng | H8: Chưa làm
A9: 46300 | B9: Thứ 2 | C9: Zalo OA | D9: Đời sống SEIU | E9: Tin tuần: lịch khai giảng, nhắc thi thử TOPIK Master | H9: Chưa làm
A10: 46301 | B10: Thứ 3 | C10: TikTok + Reels | D10: Đời sống SEIU | E10: Khoảnh khắc nhận visa | F10: 4 | H10: Chưa làm
A11: 46301 | B11: Thứ 3 | C11: Website + Facebook | D11: Thầy Bửu | E11: Chia sẻ bài blog: Visa D4-1 và D2 khác nhau thế nào? | H11: Chưa làm
A12: 46302 | B12: Thứ 4 | C12: TikTok + Reels | D12: Minh bạch chi phí | E12: Cảnh báo 3 chiêu "vẽ phí" du học | F12: 5 | H12: Chưa làm
A13: 46302 | B13: Thứ 4 | C13: Facebook | D13: Minh bạch chi phí | E13: Bài dài cho phụ huynh: 1 câu hỏi thường gặp về chi phí/hồ sơ | H13: Chưa làm
A14: 46303 | B14: Thứ 5 | C14: TikTok + Reels | D14: Đời sống SEIU | E14: Một ngày ở lớp SEIU Vị Thanh | F14: 6 | H14: Chưa làm
A15: 46303 | B15: Thứ 5 | C15: Website + Facebook | D15: Du học thật | E15: Chia sẻ bài blog: Hồ sơ du học Hàn Quốc cần những gì? | H15: Chưa làm
A16: 46304 | B16: Thứ 6 | C16: TikTok + Reels | D16: Học tiếng Hàn | E16: Người miền Tây nói tiếng Hàn: lỗi hay gặp | F16: 7 | H16: Chưa làm
A17: 46304 | B17: Thứ 6 | C17: Facebook | D17: Du học thật | E17: Chia sẻ câu chuyện 1 học viên SEIU ở Hàn | H17: Chưa làm
A18: 46305 | B18: Thứ 7 | C18: Facebook | D18: Học tiếng Hàn | E18: Mini quiz tiếng Hàn – trả lời ở bình luận | H18: Chưa làm
A19: 46305 | B19: Thứ 7 | C19: Facebook Live | D19: Thầy Bửu | E19: Livestream hỏi đáp du học Hàn cùng Thầy Bửu (20:00) | H19: Chưa làm
A20: 46307 | B20: Thứ 2 | C20: TikTok + Reels | D20: Thầy Bửu | E20: Học lực trung bình có du học được không? | F20: 8 | H20: Chưa làm
A21: 46307 | B21: Thứ 2 | C21: Facebook | D21: Đời sống SEIU | E21: Album ảnh lớp tuần qua + lịch khai giảng | H21: Chưa làm
A22: 46307 | B22: Thứ 2 | C22: Zalo OA | D22: Đời sống SEIU | E22: Tin tuần: lịch khai giảng, nhắc thi thử TOPIK Master | H22: Chưa làm
A23: 46308 | B23: Thứ 3 | C23: TikTok + Reels | D23: Du học thật | E23: Học viên SEIU gọi video từ Hàn về lớp cũ | F23: 9 | H23: Chưa làm
A24: 46308 | B24: Thứ 3 | C24: Website + Facebook | D24: Minh bạch chi phí | E24: Chia sẻ bài blog: 7 dấu hiệu trung tâm du học uy tín | H24: Chưa làm
A25: 46309 | B25: Thứ 4 | C25: TikTok + Reels | D25: Học tiếng Hàn | E25: Thi thử TOPIK Master miễn phí | F25: 10 | H25: Chưa làm
A26: 46309 | B26: Thứ 4 | C26: Facebook | D26: Minh bạch chi phí | E26: Bài dài cho phụ huynh: 1 câu hỏi thường gặp về chi phí/hồ sơ | H26: Chưa làm
A27: 46310 | B27: Thứ 5 | C27: TikTok + Reels | D27: Học tiếng Hàn | E27: 5 câu chào hỏi phải biết | F27: 11 | H27: Chưa làm
A28: 46310 | B28: Thứ 5 | C28: Website + Facebook | D28: Thầy Bửu | E28: Chia sẻ bài blog: Có nên du học Hàn sau lớp 12? | H28: Chưa làm
A29: 46311 | B29: Thứ 6 | C29: TikTok + Reels | D29: Du học thật | E29: Tiền nhà, tiền ăn ở Hàn 1 tháng | F29: 12 | H29: Chưa làm
A30: 46311 | B30: Thứ 6 | C30: Facebook | D30: Du học thật | E30: Chia sẻ câu chuyện 1 học viên SEIU ở Hàn | H30: Chưa làm
A31: 46312 | B31: Thứ 7 | C31: Facebook | D31: Học tiếng Hàn | E31: Mini quiz tiếng Hàn – trả lời ở bình luận | H31: Chưa làm
A32: 46314 | B32: Thứ 2 | C32: TikTok + Reels | D32: Minh bạch chi phí | E32: Hợp đồng SEIU có gì? | F32: 13 | H32: Chưa làm
A33: 46314 | B33: Thứ 2 | C33: Facebook | D33: Đời sống SEIU | E33: Album ảnh lớp tuần qua + lịch khai giảng | H33: Chưa làm
A34: 46314 | B34: Thứ 2 | C34: Zalo OA | D34: Đời sống SEIU | E34: Tin tuần: lịch khai giảng, nhắc thi thử TOPIK Master | H34: Chưa làm
A35: 46315 | B35: Thứ 3 | C35: TikTok + Reels | D35: Học tiếng Hàn | E35: Học bảng chữ cái trong 60 giây | F35: 14 | H35: Chưa làm
A36: 46315 | B36: Thứ 3 | C36: Website + Facebook | D36: Học tiếng Hàn | E36: Chia sẻ bài blog: Tự học Hangeul trong 7 ngày | H36: Chưa làm
A37: 46316 | B37: Thứ 4 | C37: TikTok + Reels | D37: Đời sống SEIU | E37: Bảng Thành Tích tháng này | F37: 15 | H37: Chưa làm
A38: 46316 | B38: Thứ 4 | C38: Facebook | D38: Minh bạch chi phí | E38: Bài dài cho phụ huynh: 1 câu hỏi thường gặp về chi phí/hồ sơ | H38: Chưa làm
A39: 46317 | B39: Thứ 5 | C39: TikTok + Reels | D39: Thầy Bửu | E39: D4-1 hay D2: chọn hệ nào? | F39: 16 | H39: Chưa làm
A40: 46317 | B40: Thứ 5 | C40: Website + Facebook | D40: Học tiếng Hàn | E40: Chia sẻ bài blog: 30 câu giao tiếp tiếng Hàn cơ bản | H40: Chưa làm
...

Sheet KPI tháng
A1: Chỉ số | B1: Mục tiêu tháng 10 | C1: Thực tế | D1: % đạt
A2: Follower TikTok (tổng) | B2: 1000 | D2: =IF(OR(B2="",C2=""),"",C2/B2)
A3: Follower fanpage mới trong tháng | B3: 300 | D3: =IF(OR(B3="",C3=""),"",C3/B3)
A4: Lượt thi TOPIK Master | B4: 300 | D4: =IF(OR(B4="",C4=""),"",C4/B4)
A5: Lead (tên + SĐT) | B5: 100 | D5: =IF(OR(B5="",C5=""),"",C5/B5)
A6: Học viên đăng ký mới | B6: 15 | D6: =IF(OR(B6="",C6=""),"",C6/B6)
A7: Đánh giá Google mới | B7: 15 | D7: =IF(OR(B7="",C7=""),"",C7/B7)
A8: Hồ sơ du học ký mới | D8: =IF(OR(B8="",C8=""),"",C8/B8)
A9: Mục tiêu (chữ xanh) là con số gợi ý, chỉnh theo thực tế. "Hồ sơ du học ký mới": tự điền mục tiêu theo năng lực tư vấn.
A11: Tiến độ lịch đăng (tự tính từ tab "Lịch tháng 10")
A12: Trụ cột | B12: Số bài kế hoạch | C12: Đã đăng | D12: Tỷ lệ
A13: Học tiếng Hàn | B13: =COUNTIF('Lịch tháng 10'!$D$2:$D$56,A13) | C13: =COUNTIFS('Lịch tháng 10'!$D$2:$D$56,A13,'Lịch tháng 10'!$H$2:$H$56,"Đã đăng") | D13: =IF(B13=0,"",C13/B13)
A14: Du học thật | B14: =COUNTIF('Lịch tháng 10'!$D$2:$D$56,A14) | C14: =COUNTIFS('Lịch tháng 10'!$D$2:$D$56,A14,'Lịch tháng 10'!$H$2:$H$56,"Đã đăng") | D14: =IF(B14=0,"",C14/B14)
A15: Đời sống SEIU | B15: =COUNTIF('Lịch tháng 10'!$D$2:$D$56,A15) | C15: =COUNTIFS('Lịch tháng 10'!$D$2:$D$56,A15,'Lịch tháng 10'!$H$2:$H$56,"Đã đăng") | D15: =IF(B15=0,"",C15/B15)
A16: Minh bạch chi phí | B16: =COUNTIF('Lịch tháng 10'!$D$2:$D$56,A16) | C16: =COUNTIFS('Lịch tháng 10'!$D$2:$D$56,A16,'Lịch tháng 10'!$H$2:$H$56,"Đã đăng") | D16: =IF(B16=0,"",C16/B16)
A17: Thầy Bửu | B17: =COUNTIF('Lịch tháng 10'!$D$2:$D$56,A17) | C17: =COUNTIFS('Lịch tháng 10'!$D$2:$D$56,A17,'Lịch tháng 10'!$H$2:$H$56,"Đã đăng") | D17: =IF(B17=0,"",C17/B17)
A18: Tổng | B18: =SUM(B13:B17) | C18: =SUM(C13:C17) | D18: =IF(B18=0,"",C18/B18)
